2019-01-16 11:59:12,580 ERROR: Exception on /reset_password_request [POST] [in /Users/MasonBaran/first_flask/venv/lib/python3.7/site-packages/flask/app.py:1761]
Traceback (most recent call last):
  File "/Users/MasonBaran/first_flask/venv/lib/python3.7/site-packages/flask/app.py", line 2292, in wsgi_app
    response = self.full_dispatch_request()
  File "/Users/MasonBaran/first_flask/venv/lib/python3.7/site-packages/flask/app.py", line 1815, in full_dispatch_request
    rv = self.handle_user_exception(e)
  File "/Users/MasonBaran/first_flask/venv/lib/python3.7/site-packages/flask/app.py", line 1718, in handle_user_exception
    reraise(exc_type, exc_value, tb)
  File "/Users/MasonBaran/first_flask/venv/lib/python3.7/site-packages/flask/_compat.py", line 35, in reraise
    raise value
  File "/Users/MasonBaran/first_flask/venv/lib/python3.7/site-packages/flask/app.py", line 1813, in full_dispatch_request
    rv = self.dispatch_request()
  File "/Users/MasonBaran/first_flask/venv/lib/python3.7/site-packages/flask/app.py", line 1799, in dispatch_request
    return self.view_functions[rule.endpoint](**req.view_args)
  File "/Users/MasonBaran/first_flask/app/routes.py", line 163, in reset_password_request
    send_password_request(user)
  File "/Users/MasonBaran/first_flask/app/email.py", line 16, in send_password_request
    sender=app.config['Admins'][0],
KeyError: 'Admins'
2019-01-16 11:59:49,072 INFO: Microblog startup [in /Users/MasonBaran/first_flask/app/__init__.py:45]
2019-01-16 12:03:10,606 INFO: Microblog startup [in /Users/MasonBaran/first_flask/app/__init__.py:45]
2019-01-16 12:07:06,900 INFO: Microblog startup [in /Users/MasonBaran/first_flask/app/__init__.py:45]
2019-01-16 12:07:36,902 ERROR: Exception on /reset_password/eyJ0eXAiOiJKV1QiLCJhbGciOiJIUzI1NiJ9.eyJyZXNldF9wYXNzd29yZCI6MSwiZXhwIjoxNTQ3NjYyNjQxLjY3MzExMjJ9.JTle0pbXeoPUNYesdVvtX70FnN8EqwZSBmBxeyti1e0 [GET] [in /Users/MasonBaran/first_flask/venv/lib/python3.7/site-packages/flask/app.py:1761]
Traceback (most recent call last):
  File "/Users/MasonBaran/first_flask/venv/lib/python3.7/site-packages/flask/app.py", line 2292, in wsgi_app
    response = self.full_dispatch_request()
  File "/Users/MasonBaran/first_flask/venv/lib/python3.7/site-packages/flask/app.py", line 1815, in full_dispatch_request
    rv = self.handle_user_exception(e)
  File "/Users/MasonBaran/first_flask/venv/lib/python3.7/site-packages/flask/app.py", line 1718, in handle_user_exception
    reraise(exc_type, exc_value, tb)
  File "/Users/MasonBaran/first_flask/venv/lib/python3.7/site-packages/flask/_compat.py", line 35, in reraise
    raise value
  File "/Users/MasonBaran/first_flask/venv/lib/python3.7/site-packages/flask/app.py", line 1813, in full_dispatch_request
    rv = self.dispatch_request()
  File "/Users/MasonBaran/first_flask/venv/lib/python3.7/site-packages/flask/app.py", line 1799, in dispatch_request
    return self.view_functions[rule.endpoint](**req.view_args)
  File "/Users/MasonBaran/first_flask/app/routes.py", line 173, in reset_password
    user = User.verify_password_token(token)
AttributeError: type object 'User' has no attribute 'verify_password_token'
2019-01-16 12:08:06,542 INFO: Microblog startup [in /Users/MasonBaran/first_flask/app/__init__.py:45]
2019-01-16 12:08:37,833 ERROR: Exception on /reset_password/eyJ0eXAiOiJKV1QiLCJhbGciOiJIUzI1NiJ9.eyJyZXNldF9wYXNzd29yZCI6MSwiZXhwIjoxNTQ3NjYyNzA5LjU5NjY5NH0._yFQ1NZYViqOM-mBwv4F7obQ_gr7BGc-0TPccX_o7dg [GET] [in /Users/MasonBaran/first_flask/venv/lib/python3.7/site-packages/flask/app.py:1761]
Traceback (most recent call last):
  File "/Users/MasonBaran/first_flask/venv/lib/python3.7/site-packages/flask/app.py", line 2292, in wsgi_app
    response = self.full_dispatch_request()
  File "/Users/MasonBaran/first_flask/venv/lib/python3.7/site-packages/flask/app.py", line 1815, in full_dispatch_request
    rv = self.handle_user_exception(e)
  File "/Users/MasonBaran/first_flask/venv/lib/python3.7/site-packages/flask/app.py", line 1718, in handle_user_exception
    reraise(exc_type, exc_value, tb)
  File "/Users/MasonBaran/first_flask/venv/lib/python3.7/site-packages/flask/_compat.py", line 35, in reraise
    raise value
  File "/Users/MasonBaran/first_flask/venv/lib/python3.7/site-packages/flask/app.py", line 1813, in full_dispatch_request
    rv = self.dispatch_request()
  File "/Users/MasonBaran/first_flask/venv/lib/python3.7/site-packages/flask/app.py", line 1799, in dispatch_request
    return self.view_functions[rule.endpoint](**req.view_args)
  File "/Users/MasonBaran/first_flask/app/routes.py", line 178, in reset_password
    user.set_password(form.password.data)
  File "/Users/MasonBaran/first_flask/app/models.py", line 36, in set_password
    self.password_hash = generate_password_hash(password)
  File "/Users/MasonBaran/first_flask/venv/lib/python3.7/site-packages/werkzeug/security.py", line 230, in generate_password_hash
    h, actual_method = _hash_internal(method, salt, password)
  File "/Users/MasonBaran/first_flask/venv/lib/python3.7/site-packages/werkzeug/security.py", line 192, in _hash_internal
    hashfunc=hash_func)
  File "/Users/MasonBaran/first_flask/venv/lib/python3.7/site-packages/werkzeug/security.py", line 64, in pbkdf2_hex
    rv = pbkdf2_bin(data, salt, iterations, keylen, hashfunc)
  File "/Users/MasonBaran/first_flask/venv/lib/python3.7/site-packages/werkzeug/security.py", line 104, in pbkdf2_bin
    keylen)
TypeError: a bytes-like object is required, not 'NoneType'
2019-01-16 12:12:33,688 ERROR: Exception on /reset_password/eyJ0eXAiOiJKV1QiLCJhbGciOiJIUzI1NiJ9.eyJyZXNldF9wYXNzd29yZCI6NCwiZXhwIjoxNTQ3NjYyOTQ1LjI5MjczN30.DAOcPYa5zbycyylRtylX67Og6jZTfu3jUxEuUTYl6vI [GET] [in /Users/MasonBaran/first_flask/venv/lib/python3.7/site-packages/flask/app.py:1761]
Traceback (most recent call last):
  File "/Users/MasonBaran/first_flask/venv/lib/python3.7/site-packages/flask/app.py", line 2292, in wsgi_app
    response = self.full_dispatch_request()
  File "/Users/MasonBaran/first_flask/venv/lib/python3.7/site-packages/flask/app.py", line 1815, in full_dispatch_request
    rv = self.handle_user_exception(e)
  File "/Users/MasonBaran/first_flask/venv/lib/python3.7/site-packages/flask/app.py", line 1718, in handle_user_exception
    reraise(exc_type, exc_value, tb)
  File "/Users/MasonBaran/first_flask/venv/lib/python3.7/site-packages/flask/_compat.py", line 35, in reraise
    raise value
  File "/Users/MasonBaran/first_flask/venv/lib/python3.7/site-packages/flask/app.py", line 1813, in full_dispatch_request
    rv = self.dispatch_request()
  File "/Users/MasonBaran/first_flask/venv/lib/python3.7/site-packages/flask/app.py", line 1799, in dispatch_request
    return self.view_functions[rule.endpoint](**req.view_args)
  File "/Users/MasonBaran/first_flask/app/routes.py", line 178, in reset_password
    user.set_password(form.password.data)
  File "/Users/MasonBaran/first_flask/app/models.py", line 36, in set_password
    self.password_hash = generate_password_hash(password)
  File "/Users/MasonBaran/first_flask/venv/lib/python3.7/site-packages/werkzeug/security.py", line 230, in generate_password_hash
    h, actual_method = _hash_internal(method, salt, password)
  File "/Users/MasonBaran/first_flask/venv/lib/python3.7/site-packages/werkzeug/security.py", line 192, in _hash_internal
    hashfunc=hash_func)
  File "/Users/MasonBaran/first_flask/venv/lib/python3.7/site-packages/werkzeug/security.py", line 64, in pbkdf2_hex
    rv = pbkdf2_bin(data, salt, iterations, keylen, hashfunc)
  File "/Users/MasonBaran/first_flask/venv/lib/python3.7/site-packages/werkzeug/security.py", line 104, in pbkdf2_bin
    keylen)
TypeError: a bytes-like object is required, not 'NoneType'
2019-01-16 12:15:34,798 INFO: Microblog startup [in /Users/MasonBaran/first_flask/app/__init__.py:45]
2019-01-16 12:15:55,470 ERROR: Exception on /reset_password/eyJ0eXAiOiJKV1QiLCJhbGciOiJIUzI1NiJ9.eyJyZXNldF9wYXNzd29yZCI6NCwiZXhwIjoxNTQ3NjYzMTQ0Ljk1MzMxfQ.1i80ywuf1EBLK0XOZoVdkNvaUVeIIyqH8ErTnZ4gQwo [GET] [in /Users/MasonBaran/first_flask/venv/lib/python3.7/site-packages/flask/app.py:1761]
Traceback (most recent call last):
  File "/Users/MasonBaran/first_flask/venv/lib/python3.7/site-packages/flask/app.py", line 2292, in wsgi_app
    response = self.full_dispatch_request()
  File "/Users/MasonBaran/first_flask/venv/lib/python3.7/site-packages/flask/app.py", line 1815, in full_dispatch_request
    rv = self.handle_user_exception(e)
  File "/Users/MasonBaran/first_flask/venv/lib/python3.7/site-packages/flask/app.py", line 1718, in handle_user_exception
    reraise(exc_type, exc_value, tb)
  File "/Users/MasonBaran/first_flask/venv/lib/python3.7/site-packages/flask/_compat.py", line 35, in reraise
    raise value
  File "/Users/MasonBaran/first_flask/venv/lib/python3.7/site-packages/flask/app.py", line 1813, in full_dispatch_request
    rv = self.dispatch_request()
  File "/Users/MasonBaran/first_flask/venv/lib/python3.7/site-packages/flask/app.py", line 1799, in dispatch_request
    return self.view_functions[rule.endpoint](**req.view_args)
  File "/Users/MasonBaran/first_flask/app/routes.py", line 173, in reset_password
    user = User.verify_password_token(token)
AttributeError: type object 'User' has no attribute 'verify_password_token'
2019-01-16 12:16:52,197 INFO: Microblog startup [in /Users/MasonBaran/first_flask/app/__init__.py:45]
